[2025-01-13T04:17:43.854+0000] {taskinstance.py:1956} INFO - Dependencies all met for dep_context=non-requeueable deps ti=<TaskInstance: weather_pipeline.save_to_postgres scheduled__2025-01-12T00:00:00+00:00 [queued]>
[2025-01-13T04:17:43.858+0000] {taskinstance.py:1956} INFO - Dependencies all met for dep_context=requeueable deps ti=<TaskInstance: weather_pipeline.save_to_postgres scheduled__2025-01-12T00:00:00+00:00 [queued]>
[2025-01-13T04:17:43.858+0000] {taskinstance.py:2170} INFO - Starting attempt 2 of 2
[2025-01-13T04:17:43.868+0000] {taskinstance.py:2191} INFO - Executing <Task(PythonOperator): save_to_postgres> on 2025-01-12 00:00:00+00:00
[2025-01-13T04:17:43.871+0000] {standard_task_runner.py:60} INFO - Started process 149 to run task
[2025-01-13T04:17:43.873+0000] {standard_task_runner.py:87} INFO - Running: ['***', 'tasks', 'run', 'weather_pipeline', 'save_to_postgres', 'scheduled__2025-01-12T00:00:00+00:00', '--job-id', '57', '--raw', '--subdir', 'DAGS_FOLDER/weather_pipeline_dag.py', '--cfg-path', '/tmp/tmpafzj_lvg']
[2025-01-13T04:17:43.874+0000] {standard_task_runner.py:88} INFO - Job 57: Subtask save_to_postgres
[2025-01-13T04:17:43.904+0000] {task_command.py:423} INFO - Running <TaskInstance: weather_pipeline.save_to_postgres scheduled__2025-01-12T00:00:00+00:00 [running]> on host 6c6383cc9f1d
[2025-01-13T04:17:43.950+0000] {taskinstance.py:2480} INFO - Exporting env vars: AIRFLOW_CTX_DAG_OWNER='***' AIRFLOW_CTX_DAG_ID='weather_pipeline' AIRFLOW_CTX_TASK_ID='save_to_postgres' AIRFLOW_CTX_EXECUTION_DATE='2025-01-12T00:00:00+00:00' AIRFLOW_CTX_TRY_NUMBER='2' AIRFLOW_CTX_DAG_RUN_ID='scheduled__2025-01-12T00:00:00+00:00'
[2025-01-13T04:17:43.951+0000] {logging_mixin.py:188} INFO - Saving data to PostgreSQL...
[2025-01-13T04:17:43.952+0000] {connection.py:473} ERROR - Unable to retrieve connection from secrets backend (EnvironmentVariablesBackend). Checking subsequent secrets backend.
Traceback (most recent call last):
  File "/home/airflow/.local/lib/python3.8/site-packages/airflow/models/connection.py", line 468, in get_connection_from_secrets
    conn = secrets_backend.get_connection(conn_id=conn_id)
  File "/home/airflow/.local/lib/python3.8/site-packages/airflow/secrets/base_secrets.py", line 96, in get_connection
    value = self.get_conn_value(conn_id=conn_id)
  File "/home/airflow/.local/lib/python3.8/site-packages/airflow/secrets/environment_variables.py", line 51, in get_conn_value
    return os.environ.get(CONN_ENV_PREFIX + conn_id.upper())
AttributeError: 'int' object has no attribute 'upper'
[2025-01-13T04:17:43.957+0000] {connection.py:473} ERROR - Unable to retrieve connection from secrets backend (MetastoreBackend). Checking subsequent secrets backend.
Traceback (most recent call last):
  File "/home/airflow/.local/lib/python3.8/site-packages/sqlalchemy/engine/base.py", line 1910, in _execute_context
    self.dialect.do_execute(
  File "/home/airflow/.local/lib/python3.8/site-packages/sqlalchemy/engine/default.py", line 736, in do_execute
    cursor.execute(statement, parameters)
psycopg2.errors.UndefinedFunction: operator does not exist: character varying = integer
LINE 3: WHERE connection.conn_id = 1000 
                                 ^
HINT:  No operator matches the given name and argument types. You might need to add explicit type casts.


The above exception was the direct cause of the following exception:

Traceback (most recent call last):
  File "/home/airflow/.local/lib/python3.8/site-packages/airflow/models/connection.py", line 468, in get_connection_from_secrets
    conn = secrets_backend.get_connection(conn_id=conn_id)
  File "/home/airflow/.local/lib/python3.8/site-packages/airflow/utils/session.py", line 79, in wrapper
    return func(*args, session=session, **kwargs)
  File "/home/airflow/.local/lib/python3.8/site-packages/airflow/secrets/metastore.py", line 42, in get_connection
    return MetastoreBackend._fetch_connection(conn_id, session=session)
  File "/home/airflow/.local/lib/python3.8/site-packages/airflow/api_internal/internal_api_call.py", line 114, in wrapper
    return func(*args, **kwargs)
  File "/home/airflow/.local/lib/python3.8/site-packages/airflow/utils/session.py", line 76, in wrapper
    return func(*args, **kwargs)
  File "/home/airflow/.local/lib/python3.8/site-packages/airflow/secrets/metastore.py", line 73, in _fetch_connection
    conn = session.scalar(select(Connection).where(Connection.conn_id == conn_id).limit(1))
  File "/home/airflow/.local/lib/python3.8/site-packages/sqlalchemy/orm/session.py", line 1747, in scalar
    return self.execute(
  File "/home/airflow/.local/lib/python3.8/site-packages/sqlalchemy/orm/session.py", line 1717, in execute
    result = conn._execute_20(statement, params or {}, execution_options)
  File "/home/airflow/.local/lib/python3.8/site-packages/sqlalchemy/engine/base.py", line 1710, in _execute_20
    return meth(self, args_10style, kwargs_10style, execution_options)
  File "/home/airflow/.local/lib/python3.8/site-packages/sqlalchemy/sql/elements.py", line 334, in _execute_on_connection
    return connection._execute_clauseelement(
  File "/home/airflow/.local/lib/python3.8/site-packages/sqlalchemy/engine/base.py", line 1577, in _execute_clauseelement
    ret = self._execute_context(
  File "/home/airflow/.local/lib/python3.8/site-packages/sqlalchemy/engine/base.py", line 1953, in _execute_context
    self._handle_dbapi_exception(
  File "/home/airflow/.local/lib/python3.8/site-packages/sqlalchemy/engine/base.py", line 2134, in _handle_dbapi_exception
    util.raise_(
  File "/home/airflow/.local/lib/python3.8/site-packages/sqlalchemy/util/compat.py", line 211, in raise_
    raise exception
  File "/home/airflow/.local/lib/python3.8/site-packages/sqlalchemy/engine/base.py", line 1910, in _execute_context
    self.dialect.do_execute(
  File "/home/airflow/.local/lib/python3.8/site-packages/sqlalchemy/engine/default.py", line 736, in do_execute
    cursor.execute(statement, parameters)
sqlalchemy.exc.ProgrammingError: (psycopg2.errors.UndefinedFunction) operator does not exist: character varying = integer
LINE 3: WHERE connection.conn_id = 1000 
                                 ^
HINT:  No operator matches the given name and argument types. You might need to add explicit type casts.

[SQL: SELECT connection.password, connection.extra, connection.id, connection.conn_id, connection.conn_type, connection.description, connection.host, connection.schema, connection.login, connection.port, connection.is_encrypted, connection.is_extra_encrypted 
FROM connection 
WHERE connection.conn_id = %(conn_id_1)s 
 LIMIT %(param_1)s]
[parameters: {'conn_id_1': 1000, 'param_1': 1}]
(Background on this error at: https://sqlalche.me/e/14/f405)
[2025-01-13T04:17:43.965+0000] {taskinstance.py:2698} ERROR - Task failed with exception
Traceback (most recent call last):
  File "/home/airflow/.local/lib/python3.8/site-packages/airflow/models/taskinstance.py", line 433, in _execute_task
    result = execute_callable(context=context, **execute_callable_kwargs)
  File "/home/airflow/.local/lib/python3.8/site-packages/airflow/operators/python.py", line 199, in execute
    return_value = self.execute_callable()
  File "/home/airflow/.local/lib/python3.8/site-packages/airflow/operators/python.py", line 216, in execute_callable
    return self.python_callable(*self.op_args, **self.op_kwargs)
  File "/opt/airflow/dags/weather_pipeline_dag.py", line 57, in save_to_postgres
    conn = BaseHook.get_connection(POSTGRES_CONN_ID)
  File "/home/airflow/.local/lib/python3.8/site-packages/airflow/hooks/base.py", line 82, in get_connection
    conn = Connection.get_connection_from_secrets(conn_id)
  File "/home/airflow/.local/lib/python3.8/site-packages/airflow/models/connection.py", line 479, in get_connection_from_secrets
    raise AirflowNotFoundException(f"The conn_id `{conn_id}` isn't defined")
airflow.exceptions.AirflowNotFoundException: The conn_id `1000` isn't defined
[2025-01-13T04:17:43.967+0000] {taskinstance.py:1138} INFO - Marking task as FAILED. dag_id=weather_pipeline, task_id=save_to_postgres, execution_date=20250112T000000, start_date=20250113T041743, end_date=20250113T041743
[2025-01-13T04:17:43.974+0000] {standard_task_runner.py:107} ERROR - Failed to execute job 57 for task save_to_postgres (The conn_id `1000` isn't defined; 149)
[2025-01-13T04:17:44.005+0000] {local_task_job_runner.py:234} INFO - Task exited with return code 1
[2025-01-13T04:17:44.016+0000] {taskinstance.py:3280} INFO - 0 downstream tasks scheduled from follow-on schedule check
