[2025-01-13T21:43:52.172+0000] {taskinstance.py:1956} INFO - Dependencies all met for dep_context=non-requeueable deps ti=<TaskInstance: weather_pipeline.save_to_postgres manual__2025-01-13T21:38:47.566690+00:00 [queued]>
[2025-01-13T21:43:52.177+0000] {taskinstance.py:1956} INFO - Dependencies all met for dep_context=requeueable deps ti=<TaskInstance: weather_pipeline.save_to_postgres manual__2025-01-13T21:38:47.566690+00:00 [queued]>
[2025-01-13T21:43:52.177+0000] {taskinstance.py:2170} INFO - Starting attempt 2 of 2
[2025-01-13T21:43:52.186+0000] {taskinstance.py:2191} INFO - Executing <Task(PythonOperator): save_to_postgres> on 2025-01-13 21:38:47.566690+00:00
[2025-01-13T21:43:52.189+0000] {standard_task_runner.py:60} INFO - Started process 164 to run task
[2025-01-13T21:43:52.191+0000] {standard_task_runner.py:87} INFO - Running: ['***', 'tasks', 'run', 'weather_pipeline', 'save_to_postgres', 'manual__2025-01-13T21:38:47.566690+00:00', '--job-id', '64', '--raw', '--subdir', 'DAGS_FOLDER/weather_pipeline_dag.py', '--cfg-path', '/tmp/tmpirll0cme']
[2025-01-13T21:43:52.192+0000] {standard_task_runner.py:88} INFO - Job 64: Subtask save_to_postgres
[2025-01-13T21:43:52.219+0000] {task_command.py:423} INFO - Running <TaskInstance: weather_pipeline.save_to_postgres manual__2025-01-13T21:38:47.566690+00:00 [running]> on host b7e7ff87c18c
[2025-01-13T21:43:52.266+0000] {taskinstance.py:2480} INFO - Exporting env vars: AIRFLOW_CTX_DAG_OWNER='***' AIRFLOW_CTX_DAG_ID='weather_pipeline' AIRFLOW_CTX_TASK_ID='save_to_postgres' AIRFLOW_CTX_EXECUTION_DATE='2025-01-13T21:38:47.566690+00:00' AIRFLOW_CTX_TRY_NUMBER='2' AIRFLOW_CTX_DAG_RUN_ID='manual__2025-01-13T21:38:47.566690+00:00'
[2025-01-13T21:43:52.267+0000] {logging_mixin.py:188} INFO - Saving data to PostgreSQL...
[2025-01-13T21:43:52.276+0000] {taskinstance.py:2698} ERROR - Task failed with exception
Traceback (most recent call last):
  File "/home/airflow/.local/lib/python3.8/site-packages/airflow/models/taskinstance.py", line 433, in _execute_task
    result = execute_callable(context=context, **execute_callable_kwargs)
  File "/home/airflow/.local/lib/python3.8/site-packages/airflow/operators/python.py", line 199, in execute
    return_value = self.execute_callable()
  File "/home/airflow/.local/lib/python3.8/site-packages/airflow/operators/python.py", line 216, in execute_callable
    return self.python_callable(*self.op_args, **self.op_kwargs)
  File "/opt/airflow/dags/weather_pipeline_dag.py", line 57, in save_to_postgres
    conn = BaseHook.get_connection(POSTGRES_CONN_ID)
  File "/home/airflow/.local/lib/python3.8/site-packages/airflow/hooks/base.py", line 82, in get_connection
    conn = Connection.get_connection_from_secrets(conn_id)
  File "/home/airflow/.local/lib/python3.8/site-packages/airflow/models/connection.py", line 479, in get_connection_from_secrets
    raise AirflowNotFoundException(f"The conn_id `{conn_id}` isn't defined")
airflow.exceptions.AirflowNotFoundException: The conn_id `my_postgres_conn` isn't defined
[2025-01-13T21:43:52.278+0000] {taskinstance.py:1138} INFO - Marking task as FAILED. dag_id=weather_pipeline, task_id=save_to_postgres, execution_date=20250113T213847, start_date=20250113T214352, end_date=20250113T214352
[2025-01-13T21:43:52.285+0000] {standard_task_runner.py:107} ERROR - Failed to execute job 64 for task save_to_postgres (The conn_id `my_postgres_conn` isn't defined; 164)
[2025-01-13T21:43:52.323+0000] {local_task_job_runner.py:234} INFO - Task exited with return code 1
[2025-01-13T21:43:52.333+0000] {taskinstance.py:3280} INFO - 0 downstream tasks scheduled from follow-on schedule check
