[2025-01-13T21:45:22.869+0000] {scheduler_job_runner.py:1586} WARNING - Marking task instance <TaskInstance: weather_pipeline.collect_weather_data manual__2025-01-13T21:35:04.998647+00:00 [queued]> stuck in queued as failed. If the task instance has available retries, it will be retried.
[2025-01-13T21:45:23.025+0000] {scheduler_job_runner.py:781} ERROR - Executor reports task instance <TaskInstance: weather_pipeline.collect_weather_data manual__2025-01-13T21:35:04.998647+00:00 [queued]> finished (failed) although the task says it's queued. (Info: None) Was the task killed externally?
